<?xml version="1.0" ?>
<!-- =================================================================================== -->
<!-- |    This document was autogenerated by xacro from delta_manipulator.xacro        | -->
<!-- |    EDITING THIS FILE BY HAND IS NOT RECOMMENDED                                 | -->
<!-- =================================================================================== -->
<!-- This file specifies the structure of the delta manipulator. It uses helper macros from the utils xacro and takes parameters from the parameters xacro file. -->
<robot name="delta_manipulator">
   #Just give every link a mass of 1 for now, add specific masses to increase fidelity
  # Maybe some actuator joint limits?


  <link name="bicep_1">
    <visual>
      <geometry>
        <cylinder length="0.2" radius="0.025"/>
      </geometry>
      <origin rpy="0 0 0" xyz="0 0 0"/>
       # Fill in
      
    </visual>
    <collision>
      <geometry>
        <cylinder length="0.2" radius="0.025"/>
      </geometry>
      <origin rpy=" 0 0 0" xyz="0 0 0"/>
       # Fill in
      
    </collision>
    <inertial>
      <mass value="1.0"/>
      <origin rpy="0 0 0" xyz="0 0 0"/>
      <inertia ixx="0.003489583333333334" ixy="0.0" ixz="0.0" iyy="0.00031250000000000006" iyz="0.0" izz="0.003489583333333334"/>
    </inertial>
  </link>
  <!-- Gazebo simulation settings -->
  <gazebo reference="bicep_1">
    <selfCollide>true</selfCollide>
    <static>false</static>
    <turnGravityOff>true</turnGravityOff>
    <material>Gazebo/White</material>
  </gazebo>
  <link name="bicep_2">
    <visual>
      <geometry>
        <cylinder length="0.2" radius="0.025"/>
      </geometry>
      <origin rpy="0 0 0" xyz="0 0 0"/>
       # Fill in
      
    </visual>
    <collision>
      <geometry>
        <cylinder length="0.2" radius="0.025"/>
      </geometry>
      <origin rpy=" 0 0 0" xyz="0 0 0"/>
       # Fill in
      
    </collision>
    <inertial>
      <mass value="1.0"/>
      <origin rpy="0 0 0" xyz="0 0 0"/>
      <inertia ixx="0.003489583333333334" ixy="0.0" ixz="0.0" iyy="0.00031250000000000006" iyz="0.0" izz="0.003489583333333334"/>
    </inertial>
  </link>
  <!-- Gazebo simulation settings -->
  <gazebo reference="bicep_2">
    <selfCollide>true</selfCollide>
    <static>false</static>
    <turnGravityOff>true</turnGravityOff>
    <material>Gazebo/White</material>
  </gazebo>
  <link name="bicep_3">
    <visual>
      <geometry>
        <cylinder length="0.2" radius="0.025"/>
      </geometry>
      <origin rpy="0 0 0" xyz="0 0 0"/>
       # Fill in
      
    </visual>
    <collision>
      <geometry>
        <cylinder length="0.2" radius="0.025"/>
      </geometry>
      <origin rpy=" 0 0 0" xyz="0 0 0"/>
       # Fill in
      
    </collision>
    <inertial>
      <mass value="1.0"/>
      <origin rpy="0 0 0" xyz="0 0 0"/>
      <inertia ixx="0.003489583333333334" ixy="0.0" ixz="0.0" iyy="0.00031250000000000006" iyz="0.0" izz="0.003489583333333334"/>
    </inertial>
  </link>
  <!-- Gazebo simulation settings -->
  <gazebo reference="bicep_3">
    <selfCollide>true</selfCollide>
    <static>false</static>
    <turnGravityOff>true</turnGravityOff>
    <material>Gazebo/White</material>
  </gazebo>
  <link name="forearm_1">
    <visual>
      <geometry>
        <cylinder length="0.4" radius="0.025"/>
      </geometry>
      <origin rpy="0 0 0" xyz="0 0 0"/>
       # Fill in
      
    </visual>
    <collision>
      <geometry>
        <cylinder length="0.4" radius="0.025"/>
      </geometry>
      <origin rpy=" 0 0 0" xyz="0 0 0"/>
       # Fill in
      
    </collision>
    <inertial>
      <mass value="1.0"/>
      <origin rpy="0 0 0" xyz="0 0 0"/>
      <inertia ixx="0.013489583333333334" ixy="0.0" ixz="0.0" iyy="0.00031250000000000006" iyz="0.0" izz="0.013489583333333334"/>
    </inertial>
  </link>
  <!-- Gazebo simulation settings -->
  <gazebo reference="forearm_1">
    <selfCollide>true</selfCollide>
    <static>false</static>
    <turnGravityOff>true</turnGravityOff>
    <material>Gazebo/White</material>
  </gazebo>
  <link name="forearm_2">
    <visual>
      <geometry>
        <cylinder length="0.4" radius="0.025"/>
      </geometry>
      <origin rpy="0 0 0" xyz="0 0 0"/>
       # Fill in
      
    </visual>
    <collision>
      <geometry>
        <cylinder length="0.4" radius="0.025"/>
      </geometry>
      <origin rpy=" 0 0 0" xyz="0 0 0"/>
       # Fill in
      
    </collision>
    <inertial>
      <mass value="1.0"/>
      <origin rpy="0 0 0" xyz="0 0 0"/>
      <inertia ixx="0.013489583333333334" ixy="0.0" ixz="0.0" iyy="0.00031250000000000006" iyz="0.0" izz="0.013489583333333334"/>
    </inertial>
  </link>
  <!-- Gazebo simulation settings -->
  <gazebo reference="forearm_2">
    <selfCollide>true</selfCollide>
    <static>false</static>
    <turnGravityOff>true</turnGravityOff>
    <material>Gazebo/White</material>
  </gazebo>
  <link name="forearm_3">
    <visual>
      <geometry>
        <cylinder length="0.4" radius="0.025"/>
      </geometry>
      <origin rpy="0 0 0" xyz="0 0 0"/>
       # Fill in
      
    </visual>
    <collision>
      <geometry>
        <cylinder length="0.4" radius="0.025"/>
      </geometry>
      <origin rpy=" 0 0 0" xyz="0 0 0"/>
       # Fill in
      
    </collision>
    <inertial>
      <mass value="1.0"/>
      <origin rpy="0 0 0" xyz="0 0 0"/>
      <inertia ixx="0.013489583333333334" ixy="0.0" ixz="0.0" iyy="0.00031250000000000006" iyz="0.0" izz="0.013489583333333334"/>
    </inertial>
  </link>
  <!-- Gazebo simulation settings -->
  <gazebo reference="forearm_3">
    <selfCollide>true</selfCollide>
    <static>false</static>
    <turnGravityOff>true</turnGravityOff>
    <material>Gazebo/White</material>
  </gazebo>
  <link name="base">
    <visual>
      <geometry>
        <cylinder length="0.010000000000000002" radius="0.1"/>
      </geometry>
      <origin rpy="0 0 0" xyz="0 0 0"/>
       # Fill in
      
    </visual>
    <collision>
      <geometry>
        <cylinder length="0.010000000000000002" radius="0.1"/>
      </geometry>
      <origin rpy=" 0 0 0" xyz="0 0 0"/>
       # Fill in
      
    </collision>
    <inertial>
      <mass value="1.0"/>
      <origin rpy="0 0 0" xyz="0 0 0"/>
      <inertia ixx="0.0025083333333333338" ixy="0.0" ixz="0.0" iyy="0.005000000000000001" iyz="0.0" izz="0.0025083333333333338"/>
    </inertial>
  </link>
  <!-- Gazebo simulation settings -->
  <gazebo reference="base">
    <selfCollide>true</selfCollide>
    <static>false</static>
    <turnGravityOff>true</turnGravityOff>
    <material>Gazebo/White</material>
  </gazebo>
  <link name="end_effector">
    <visual>
      <geometry>
        <cylinder length="0.005000000000000001" radius="0.05"/>
      </geometry>
      <origin rpy="0 0 0" xyz="0 0 0"/>
       # Fill in
      
    </visual>
    <collision>
      <geometry>
        <cylinder length="0.005000000000000001" radius="0.05"/>
      </geometry>
      <origin rpy=" 0 0 0" xyz="0 0 0"/>
       # Fill in
      
    </collision>
    <inertial>
      <mass value="1.0"/>
      <origin rpy="0 0 0" xyz="0 0 0"/>
      <inertia ixx="0.0006270833333333334" ixy="0.0" ixz="0.0" iyy="0.0012500000000000002" iyz="0.0" izz="0.0006270833333333334"/>
    </inertial>
  </link>
  <!-- Gazebo simulation settings -->
  <gazebo reference="end_effector">
    <selfCollide>true</selfCollide>
    <static>false</static>
    <turnGravityOff>true</turnGravityOff>
    <material>Gazebo/White</material>
  </gazebo>
  <link name="elbow_1">
    <visual>
      <geometry>
        <box size="0.025 0.025 0.025"/>
      </geometry>
      <origin rpy="0 0 0" xyz="0 0 0"/>
       # Fill in
      
    </visual>
    <collision>
      <origin rpy="0 0 0" xyz="0 0 0"/>
       # Fill in
      
    </collision>
    <inertial>
      <mass value="0.01"/>
    </inertial>
  </link>
  <gazebo reference="elbow_1">
    <selfCollide>true</selfCollide>
    <static>false</static>
    <turnGravityOff>true</turnGravityOff>
    <material>Gazebo/Blue</material>
  </gazebo>
  <link name="elbow_2">
    <visual>
      <geometry>
        <box size="0.025 0.025 0.025"/>
      </geometry>
      <origin rpy="0 0 0" xyz="0 0 0"/>
       # Fill in
      
    </visual>
    <collision>
      <origin rpy="0 0 0" xyz="0 0 0"/>
       # Fill in
      
    </collision>
    <inertial>
      <mass value="0.01"/>
    </inertial>
  </link>
  <gazebo reference="elbow_2">
    <selfCollide>true</selfCollide>
    <static>false</static>
    <turnGravityOff>true</turnGravityOff>
    <material>Gazebo/Blue</material>
  </gazebo>
  <link name="elbow_3">
    <visual>
      <geometry>
        <box size="0.025 0.025 0.025"/>
      </geometry>
      <origin rpy="0 0 0" xyz="0 0 0"/>
       # Fill in
      
    </visual>
    <collision>
      <origin rpy="0 0 0" xyz="0 0 0"/>
       # Fill in
      
    </collision>
    <inertial>
      <mass value="0.01"/>
    </inertial>
  </link>
  <gazebo reference="elbow_3">
    <selfCollide>true</selfCollide>
    <static>false</static>
    <turnGravityOff>true</turnGravityOff>
    <material>Gazebo/Blue</material>
  </gazebo>
  <link name="wrist_1">
    <visual>
      <geometry>
        <box size="0.025 0.025 0.025"/>
      </geometry>
      <origin rpy="0 0 0" xyz="0 0 0"/>
       # Fill in
      
    </visual>
    <collision>
      <origin rpy="0 0 0" xyz="0 0 0"/>
       # Fill in
      
    </collision>
    <inertial>
      <mass value="0.01"/>
    </inertial>
  </link>
  <gazebo reference="wrist_1">
    <selfCollide>true</selfCollide>
    <static>false</static>
    <turnGravityOff>true</turnGravityOff>
    <material>Gazebo/Blue</material>
  </gazebo>
  <link name="wrist_2">
    <visual>
      <geometry>
        <box size="0.025 0.025 0.025"/>
      </geometry>
      <origin rpy="0 0 0" xyz="0 0 0"/>
       # Fill in
      
    </visual>
    <collision>
      <origin rpy="0 0 0" xyz="0 0 0"/>
       # Fill in
      
    </collision>
    <inertial>
      <mass value="0.01"/>
    </inertial>
  </link>
  <gazebo reference="wrist_2">
    <selfCollide>true</selfCollide>
    <static>false</static>
    <turnGravityOff>true</turnGravityOff>
    <material>Gazebo/Blue</material>
  </gazebo>
  <link name="wrist_3">
    <visual>
      <geometry>
        <box size="0.025 0.025 0.025"/>
      </geometry>
      <origin rpy="0 0 0" xyz="0 0 0"/>
       # Fill in
      
    </visual>
    <collision>
      <origin rpy="0 0 0" xyz="0 0 0"/>
       # Fill in
      
    </collision>
    <inertial>
      <mass value="0.01"/>
    </inertial>
  </link>
  <gazebo reference="wrist_3">
    <selfCollide>true</selfCollide>
    <static>false</static>
    <turnGravityOff>true</turnGravityOff>
    <material>Gazebo/Blue</material>
  </gazebo>
  <!-- Joints -->
  <!-- Revolute joints between base and biceps -->
  <joint name="base_to_bicep_1" type="revolute">
    <parent link="base"/>
    <child link="bicep_1"/>
    <axis/>
    <origin rpy="" xyz=""/>
  </joint>
  <joint name="base_to_bicep_2" type="revolute">
    <parent link="base"/>
    <child link="bicep_2"/>
    <axis/>
    <origin rpy="" xyz=""/>
  </joint>
  <joint name="base_to_bicep_3" type="revolute">
    <parent link="base"/>
    <child link="bicep_3"/>
    <axis/>
    <origin rpy="" xyz=""/>
  </joint>
  <!-- Continuous joints between biceps and universal elbow joint link -->
  <joint name="bicep_to_elbow_1" type="continuous">
    <parent link="bicep_1"/>
    <child link="elbow_1"/>
    <axis/>
    <origin rpy="" xyz=""/>
  </joint>
  <joint name="bicep_to_elbow_2" type="continuous">
    <parent link="bicep_2"/>
    <child link="elbow_2"/>
    <axis/>
    <origin rpy="" xyz=""/>
  </joint>
  <joint name="bicep_to_elbow_3" type="continuous">
    <parent link="bicep_3"/>
    <child link="elbow_3"/>
    <axis/>
    <origin rpy="" xyz=""/>
  </joint>
  <!-- Continuous joints between universal elbow joint links and forearm -->
  <joint name="elbow_to_forearm_1" type="continuous">
    <parent link="elbow_1"/>
    <child link="forearm_1"/>
    <axis/>
    <origin rpy="" xyz=""/>
  </joint>
  <joint name="elbow_to_forearm_2" type="continuous">
    <parent link="elbow_2"/>
    <child link="forearm_2"/>
    <axis/>
    <origin rpy="" xyz=""/>
  </joint>
  <joint name="elbow_to_forearm_3" type="continuous">
    <parent link="elbow_3"/>
    <child link="forearm_3"/>
    <axis/>
    <origin rpy="" xyz=""/>
  </joint>
  <!-- Continuous joints between forearms and universal wrist joint link -->
  <joint name="forearm_to_wrist_1" type="continuous">
    <parent link="forearm_1"/>
    <child link="wrist_1"/>
    <axis/>
    <origin rpy="" xyz=""/>
  </joint>
  <joint name="forearm_to_wrist_2" type="continuous">
    <parent link="forearm_2"/>
    <child link="wrist_2"/>
    <axis/>
    <origin rpy="" xyz=""/>
  </joint>
  <joint name="forearm_to_wrist_3" type="continuous">
    <parent link="forearm_3"/>
    <child link="wrist_3"/>
    <axis/>
    <origin rpy="" xyz=""/>
  </joint>
  <!-- Continuous joints between universal wrist joint link and ee -->
  <joint name="wrist_to_ee_1" type="continuous">
    <parent link="wrist_1"/>
    <child link="end_effector"/>
    <axis/>
    <origin rpy="" xyz=""/>
  </joint>
  <joint name="wrist_to_ee_2" type="continuous">
    <parent link="wrist_2"/>
    <child link="end_effector"/>
    <axis/>
    <origin rpy="" xyz=""/>
  </joint>
  <joint name="wrist_to_ee_3" type="continuous">
    <parent link="wrist_3"/>
    <child link="end_effector"/>
    <axis/>
    <origin rpy="" xyz=""/>
  </joint>
</robot>

